Workbook

Sheet Summary
A1: PHARMACEUTICAL SERVICES FINANCIAL ANALYSIS - WORKING FILE (Charles River Laboratories, NYSE: CRL)
A4: TABLE 1 - FULL YEAR SEGMENT REVENUE & GAAP OPERATING INCOME ($000s)
A5: This workbook uses Charles River Laboratories' publicly disclosed segment financials (RMS, DSA, Manufacturing) to build a working understanding of pharmaceutical services financial modelling. It applies variance analysis, margin and KPI reporting, live formula driven modelling, and clear stakeholder facing commentary, skills relevant across FP&A and commercial finance roles in the sector. Every figure traces to a cited public filing (see 'Sources' tab), nothing is estimated or invented.
A7: TAB GUIDE
A8: Tab | B8: Contents
A9: 1. Raw Data | B9: Segment revenue, GAAP/Non-GAAP margins (annual & quarterly), organic growth bridge, Product/Service split, FY26 guidance
A10: 2. Variance Analysis | B10: Revenue & operating income variance FY25 vs FY24, driver commentary, organic growth bridge
A11: 3. Margin Trend | B11: GAAP vs Non-GAAP margin trend by segment, annual & quarterly, with chart
A12: 4. Product-Service Mix | B12: Total company revenue mix shift, driver commentary, chart
A13: Sources | B13: Every source document, date, URL, and what it was used for
A15: COLOUR CONVENTION
A16: Blue text | B16: Hardcoded, verified fact sourced directly from a filing
A17: Green text | B17: Live formula linking to another tab in this workbook
A18: Black text | B18: Calculated on the current tab
A19: Grey italic | B19: Note, caveat, or explicitly flagged data gap ('n/a')

Sheet 1. Raw Data
A1: CHARLES RIVER LABORATORIES (NYSE: CRL) - RAW SEGMENT DATA
A2: All figures USD thousands. Source: Official CRL earnings releases, SEC-filed 10-K (crl-20251227.htm). Blue = verified hardcoded fact.
A4: TABLE 1 - FULL YEAR SEGMENT REVENUE & GAAP OPERATING INCOME ($000s)
A5: Segment | B5: FY2024 Revenue | C5: FY2025 Revenue | D5: FY2024 Op Income | E5: FY2025 Op Income | F5: FY2024 Op Margin % | G5: FY2025 Op Margin % | H5: FY2024 Non-GAAP Margin % | I5: FY2025 Non-GAAP Margin %
A6: RMS | B6: 829377 | C6: 846082 | D6: n/a | E6: 44567 | F6: 0.138 | G6: =E6/C6 -> 0.052674563 | H6: 0.237 | I6: 0.248
A7: DSA | B7: 2451280 | C7: 2402891 | D7: n/a | E7: 424555 | F7: 0.181 | G7: =E7/C7 -> 0.17668508 | H7: 0.257 | I7: 0.242
A8: Manufacturing | B8: 769332 | C8: 766409 | D8: n/a | E8: -184284 | F8: -0.093 | G8: =E8/C8 -> -0.24045125 | H8: 0.274 | I8: 0.288
A9: Unallocated Corp Overhead | D9: n/a | E9: -259676
A10: TOTAL COMPANY | B10: =SUM(B6:B8) -> 4049989 | C10: =SUM(C6:C8) -> 4015382 | D10: n/a | E10: =SUM(E6:E9) -> 25162 | F10: 0.056 | G10: =E10/C10 -> 0.0062664025 | H10: 0.199 | I10: 0.198
A12: TABLE 2 - Q3 2025 QUARTER & 9-MONTH YTD DETAIL ($000s)
A13: Segment | B13: Q3'24 Rev | C13: Q3'25 Rev | D13: Q3'25 Op Income | E13: Q3'24 Op Margin % | F13: Q3'25 Op Margin % | G13: 9mo'24 Rev | H13: 9mo'25 Rev | I13: 9mo'24 Op Margin % | J13: 9mo'25 Op Margin %
A14: RMS | B14: 197824 | C14: 213474 | D14: 34553 | E14: 0.139 | F14: 0.162 | G14: 625120 | H14: 639818 | I14: 0.161 | J14: 0.178
A15: DSA | B15: 615060 | C15: 600685 | D15: 123153 | E15: 0.206 | F15: 0.205 | G15: 1847931 | H15: 1811323 | I15: 0.205 | J15: 0.188
A16: Manufacturing | B16: 196879 | C16: 190693 | D16: 39926 | E16: 0.204 | F16: 0.209 | G16: 574389 | H16: 570014 | I16: 0.193 | J16: 0.076
A17: TOTAL | B17: =SUM(B14:B16) -> 1009763 | C17: =SUM(C14:C16) -> 1004852 | D17: =SUM(D14:D16) -> 197632 | G17: =SUM(G14:G16) -> 3047440 | H17: =SUM(H14:H16) -> 3021155
A19: TABLE 3 - QUARTERLY SEGMENT REVENUE, Q4 2024 vs Q4 2025 ($000s)
A20: Segment | B20: Q4 2024 Rev | C20: Q4 2025 Rev | D20: Q4'25 Op Income | E20: Q4'24 Op Margin % | F20: Q4'25 Op Margin %
A21: RMS | B21: 204257 | C21: 206264 | D21: -69377 | E21: 0.067 | F21: -0.336
A22: DSA | B22: 603349 | C22: 591568 | D22: 84669 | E22: 0.104 | F22: 0.143
A23: Manufacturing | B23: 194943 | C23: 196395 | D23: -227651 | E23: -0.936 | F23: -1.159
A24: TOTAL | B24: =SUM(B21:B23) -> 1002549 | C24: =SUM(C21:C23) -> 994227 | D24: -283440 | E24: -0.167 | F24: -0.285
A26: TABLE 4 - Q3 2025 ORGANIC GROWTH BRIDGE (+FX/Divest % = favorable; Organic = Reported - FX - Divestiture)
A27: Segment | B27: Reported Growth % | C27: FX Impact % | D27: Divestiture Impact % | E27: Organic Growth % (check)
A28: Total CRL | B28: -0.005 | C28: 0.013 | D28: -0.002 | E28: =B28-C28-D28 -> -0.016
A29: RMS | B29: 0.079 | C29: 0.014 | D29: 0 | E29: =B29-C29-D29 -> 0.065
A30: DSA | B30: -0.023 | C30: 0.012 | D30: -0.004 | E30: =B30-C30-D30 -> -0.031
A31: Manufacturing | B31: -0.031 | C31: 0.02 | D31: 0 | E31: =B31-C31-D31 -> -0.051
A33: TABLE 5 - TOTAL REVENUE SPLIT: PRODUCT VS SERVICE ($000s)
A34: Revenue Type | B34: Q4 2024 | C34: Q4 2025 | D34: FY2024 | E34: FY2025
A35: Service Revenue | B35: 811913 | C35: 803298 | D35: 3304138 | E35: 3250099
A36: Product Revenue | B36: 190636 | C36: 190929 | D36: 745851 | E36: 765283
A37: Total | B37: =SUM(B35:B36) -> 1002549 | C37: =SUM(C35:C36) -> 994227 | D37: =SUM(D35:D36) -> 4049989 | E37: =SUM(E35:E36) -> 4015382
A39: TABLE 6 - FY2026 GUIDANCE (proxy for BUDGET line)
A40: Metric | B40: Guided Range
A41: Reported Revenue Growth | B41: Flat to +1.5%
A42: GAAP EPS | B42: $6.30 - $6.80
A43: Non-GAAP EPS | B43: $10.70 - $11.20
A46: SOURCES:
A47: Q4/FY2025 results & FY2026 Guidance: Charles River Labs press release, Feb 18 2026, ir.criver.com
A48: Q3 2025 & 9-month YTD results: Charles River Labs press release, Nov 5 2025, ir.criver.com
...

Sheet 2. Variance Analysis
A1: VARIANCE ANALYSIS - FY2025 vs FY2024 (Actual vs Prior Year)
A2: Green = formula linking to '1. Raw Data' tab. Black = calculated on this tab. This mirrors Almac JD Responsibility #1: variance against budget/forecast/prior year with driver commentary.
A4: SEGMENT REVENUE VARIANCE - FY2025 vs FY2024
A5: Segment | B5: FY2024 Revenue | C5: FY2025 Revenue | D5: $ Variance | E5: % Variance | F5: Driver Commentary
A6: RMS | B6: ='1. Raw Data'!B6 -> 829377 | C6: ='1. Raw Data'!C6 -> 846082 | D6: =C6-B6 -> 16705 | E6: =D6/B6 -> 0.020141624 | F6: Organic growth +6.5%; large research model & Cell Solutions demand offset FX headwind
A7: DSA | B7: ='1. Raw Data'!B7 -> 2451280 | C7: ='1. Raw Data'!C7 -> 2402891 | D7: =C7-B7 -> -48389 | E7: =D7/B7 -> -0.019740299 | F7: Organic decline -3.1%; lower discovery services volume + regulated safety assessment demand softness
A8: Manufacturing | B8: ='1. Raw Data'!B8 -> 769332 | C8: ='1. Raw Data'!C8 -> 766409 | D8: =C8-B8 -> -2923 | E8: =D8/B8 -> -0.0037994 | F8: Organic decline -5.1%; softer Biologics/Microbial Solutions demand across the year
A9: TOTAL COMPANY | B9: =SUM(B6:B8) -> 4049989 | C9: =SUM(C6:C8) -> 4015382 | D9: =C9-B9 -> -34607 | E9: =D9/B9 -> -0.0085449615 | F9: Organic decline -1.6% for FY2025 overall; FX and portfolio moves largely offsetting
A11: OPERATING INCOME VARIANCE - FY2025 vs FY2024
A12: Segment | B12: FY2024 Op Income | C12: FY2025 Op Income | D12: $ Variance | E12: Margin FY2024 | F12: Margin FY2025 | G12: Margin Δ (pts)
A13: RMS | B13: ='1. Raw Data'!D6 -> n/a | C13: ='1. Raw Data'!E6 -> 44567 | D13: =IFERROR(C13-B13,"n/a (FY24 $ not disclosed)") -> n/a (FY24 $ not disclosed) | E13: ='1. Raw Data'!F6 -> 0.138 | F13: ='1. Raw Data'!G6 -> 0.052674563 | G13: =(F13-E13)*100 -> -8.5325437
A14: DSA | B14: ='1. Raw Data'!D7 -> n/a | C14: ='1. Raw Data'!E7 -> 424555 | D14: =IFERROR(C14-B14,"n/a (FY24 $ not disclosed)") -> n/a (FY24 $ not disclosed) | E14: ='1. Raw Data'!F7 -> 0.181 | F14: ='1. Raw Data'!G7 -> 0.17668508 | G14: =(F14-E14)*100 -> -0.43149152
A15: Manufacturing | B15: ='1. Raw Data'!D8 -> n/a | C15: ='1. Raw Data'!E8 -> -184284 | D15: =IFERROR(C15-B15,"n/a (FY24 $ not disclosed)") -> n/a (FY24 $ not disclosed) | E15: ='1. Raw Data'!F8 -> -0.093 | F15: ='1. Raw Data'!G8 -> -0.24045125 | G15: =(F15-E15)*100 -> -14.745125
A16: TOTAL COMPANY | B16: ='1. Raw Data'!E9 -> -259676
A17: NOTE: FY2024 segment operating income $ was not disclosed in the specific press releases pulled (only margin % was). Where '$ not disclosed', the % margin columns (E,F,G) remain fully verified and are the reliable comparison.
A19: Q3 2025 ORGANIC GROWTH BRIDGE (Reported → FX → Divestiture → Organic)
A20: Segment | B20: Reported Growth % | C20: FX Impact % | D20: Divestiture Impact % | E20: Organic Growth %
A21: Total CRL | B21: ='1. Raw Data'!B28 -> -0.005 | C21: ='1. Raw Data'!C28 -> 0.013 | D21: ='1. Raw Data'!D28 -> -0.002 | E21: =B21-C21-D21 -> -0.016
A22: RMS | B22: ='1. Raw Data'!B29 -> 0.079 | C22: ='1. Raw Data'!C29 -> 0.014 | D22: ='1. Raw Data'!D29 -> 0 | E22: =B22-C22-D22 -> 0.065
A23: DSA | B23: ='1. Raw Data'!B30 -> -0.023 | C23: ='1. Raw Data'!C30 -> 0.012 | D23: ='1. Raw Data'!D30 -> -0.004 | E23: =B23-C23-D23 -> -0.031
A24: Manufacturing | B24: ='1. Raw Data'!B31 -> -0.031 | C24: ='1. Raw Data'!C31 -> 0.02 | D24: ='1. Raw Data'!D31 -> 0 | E24: =B24-C24-D24 -> -0.051

Sheet 3. Margin Trend
A1: MARGIN TREND - Is Each Segment Getting More or Less Profitable?
A2: Green = formula link to '1. Raw Data'. Black = calculated on this tab. Directly answers Almac JD's KPI reporting & margin analysis requirement.
A4: TABLE 1 - FULL-YEAR MARGIN TREND, FY2024 vs FY2025
A5: Segment | B5: FY24 GAAP | C5: FY25 GAAP | D5: GAAP Δ (pts) | E5: FY24 NonGAAP | F5: FY25 NonGAAP | G5: NonGAAP Δ (pts) | H5: GAAP↔NonGAAP Gap FY25 (pts) | I5: Direction (NonGAAP)
A6: RMS | B6: ='1. Raw Data'!F6 -> 0.138 | C6: ='1. Raw Data'!G6 -> 0.052674563 | D6: =(C6-B6)*100 -> -8.5325437 | E6: ='1. Raw Data'!H6 -> 0.237 | F6: ='1. Raw Data'!I6 -> 0.248 | G6: =(F6-E6)*100 -> 1.1 | H6: =(F6-C6)*100 -> 19.532544 | I6: =IF(G6>0,"▲ Improving",IF(G6<0,"▼ Declining","— Flat")) -> ▲ Improving
A7: DSA | B7: ='1. Raw Data'!F7 -> 0.181 | C7: ='1. Raw Data'!G7 -> 0.17668508 | D7: =(C7-B7)*100 -> -0.43149152 | E7: ='1. Raw Data'!H7 -> 0.257 | F7: ='1. Raw Data'!I7 -> 0.242 | G7: =(F7-E7)*100 -> -1.5 | H7: =(F7-C7)*100 -> 6.5314915 | I7: =IF(G7>0,"▲ Improving",IF(G7<0,"▼ Declining","— Flat")) -> ▼ Declining
A8: Manufacturing | B8: ='1. Raw Data'!F8 -> -0.093 | C8: ='1. Raw Data'!G8 -> -0.24045125 | D8: =(C8-B8)*100 -> -14.745125 | E8: ='1. Raw Data'!H8 -> 0.274 | F8: ='1. Raw Data'!I8 -> 0.288 | G8: =(F8-E8)*100 -> 1.4 | H8: =(F8-C8)*100 -> 52.845125 | I8: =IF(G8>0,"▲ Improving",IF(G8<0,"▼ Declining","— Flat")) -> ▲ Improving
A9: TOTAL COMPANY | B9: ='1. Raw Data'!F10 -> 0.056 | C9: ='1. Raw Data'!G10 -> 0.0062664025 | D9: =(C9-B9)*100 -> -4.9733597 | E9: ='1. Raw Data'!H10 -> 0.199 | F9: ='1. Raw Data'!I10 -> 0.198 | G9: =(F9-E9)*100 -> -0.1 | H9: =(F9-C9)*100 -> 19.17336 | I9: =IF(G9>0,"▲ Improving",IF(G9<0,"▼ Declining","— Flat")) -> ▼ Declining
A11: Read: FY25 GAAP margins are heavily distorted by non-cash impairments (esp. RMS Cell Solutions, Manufacturing Biologics Solutions).
A12: Non-GAAP margin trend is the reliable 'true operating profitability' signal for year-over-year comparison.
A14: TABLE 2 - QUARTERLY NON-GAAP OPERATING MARGIN TREND (same quarter, prior year vs current year)
A15: Segment | B15: Q1'24 | C15: Q1'25 | D15: Q1 Δ (pts) | E15: Q2'24 | F15: Q2'25 | G15: Q2 Δ (pts) | H15: Q3'24 | I15: Q3'25 | J15: Q3 Δ (pts) | K15: Q4'24 | L15: Q4'25 | M15: Q4 Δ (pts) | N15: FY Direction
A16: RMS | B16: =IFERROR(VALUE('1. Raw Data'!D54),"n/a") -> 0.276 | C16: =IFERROR(VALUE('1. Raw Data'!E54),"n/a") -> 0.271 | D16: =IFERROR((C16-B16)*100,"n/a") -> -0.5 | E16: =IFERROR(VALUE('1. Raw Data'!H54),"n/a") -> 0.231 | F16: =IFERROR(VALUE('1. Raw Data'!I54),"n/a") -> 0.253 | G16: =IFERROR((F16-E16)*100,"n/a") -> 2.2 | H16: =IFERROR(VALUE('1. Raw Data'!L54),"n/a") -> 0.21 | I16: =IFERROR(VALUE('1. Raw Data'!M54),"n/a") -> 0.25 | J16: =IFERROR((I16-H16)*100,"n/a") -> 4 | K16: =IFERROR(VALUE('1. Raw Data'!P54),"n/a") -> 0.228 | L16: =IFERROR(VALUE('1. Raw Data'!Q54),"n/a") -> 0.219 | M16: =IFERROR((L16-K16)*100,"n/a") -> -0.9 | N16: =IFERROR(IF(L16>K16,"▲ Improving",IF(L16<K16,"▼ Declining","— Flat")),"n/a") -> ▼ Declining
A17: DSA | B17: =IFERROR(VALUE('1. Raw Data'!D55),"n/a") -> 0.235 | C17: =IFERROR(VALUE('1. Raw Data'!E55),"n/a") -> 0.239 | D17: =IFERROR((C17-B17)*100,"n/a") -> 0.4 | E17: =IFERROR(VALUE('1. Raw Data'!H55),"n/a") -> 0.271 | F17: =IFERROR(VALUE('1. Raw Data'!I55),"n/a") -> 0.274 | G17: =IFERROR((F17-E17)*100,"n/a") -> 0.3 | H17: =IFERROR(VALUE('1. Raw Data'!L55),"n/a") -> 0.274 | I17: =IFERROR(VALUE('1. Raw Data'!M55),"n/a") -> 0.254 | J17: =IFERROR((I17-H17)*100,"n/a") -> -2 | K17: =IFERROR(VALUE('1. Raw Data'!P55),"n/a") -> 0.247 | L17: =IFERROR(VALUE('1. Raw Data'!Q55),"n/a") -> 0.201 | M17: =IFERROR((L17-K17)*100,"n/a") -> -4.6 | N17: =IFERROR(IF(L17>K17,"▲ Improving",IF(L17<K17,"▼ Declining","— Flat")),"n/a") -> ▼ Declining
A18: Manufacturing | B18: =IFERROR(VALUE('1. Raw Data'!D56),"n/a") -> n/a | C18: =IFERROR(VALUE('1. Raw Data'!E56),"n/a") -> n/a | D18: =IFERROR((C18-B18)*100,"n/a") -> n/a | E18: =IFERROR(VALUE('1. Raw Data'!H56),"n/a") -> n/a | F18: =IFERROR(VALUE('1. Raw Data'!I56),"n/a") -> n/a | G18: =IFERROR((F18-E18)*100,"n/a") -> n/a | H18: =IFERROR(VALUE('1. Raw Data'!L56),"n/a") -> n/a | I18: =IFERROR(VALUE('1. Raw Data'!M56),"n/a") -> n/a | J18: =IFERROR((I18-H18)*100,"n/a") -> n/a | K18: =IFERROR(VALUE('1. Raw Data'!P56),"n/a") -> 0.287 | L18: =IFERROR(VALUE('1. Raw Data'!Q56),"n/a") -> 0.321 | M18: =IFERROR((L18-K18)*100,"n/a") -> 3.4 | N18: =IFERROR(IF(L18>K18,"▲ Improving",IF(L18<K18,"▼ Declining","— Flat")),"n/a") -> ▲ Improving
A19: TOTAL COMPANY | B19: =IFERROR(VALUE('1. Raw Data'!D57),"n/a") -> n/a | C19: =IFERROR(VALUE('1. Raw Data'!E57),"n/a") -> n/a | D19: =IFERROR((C19-B19)*100,"n/a") -> n/a | E19: =IFERROR(VALUE('1. Raw Data'!H57),"n/a") -> n/a | F19: =IFERROR(VALUE('1. Raw Data'!I57),"n/a") -> n/a | G19: =IFERROR((F19-E19)*100,"n/a") -> n/a | H19: =IFERROR(VALUE('1. Raw Data'!L57),"n/a") -> 0.199 | I19: =IFERROR(VALUE('1. Raw Data'!M57),"n/a") -> 0.197 | J19: =IFERROR((I19-H19)*100,"n/a") -> -0.2 | K19: =IFERROR(VALUE('1. Raw Data'!P57),"n/a") -> 0.199 | L19: =IFERROR(VALUE('1. Raw Data'!Q57),"n/a") -> 0.181 | M19: =IFERROR((L19-K19)*100,"n/a") -> -1.8 | N19: =IFERROR(IF(L19>K19,"▲ Improving",IF(L19<K19,"▼ Declining","— Flat")),"n/a") -> ▼ Declining
A21: Note: Direction compares each quarter strictly to the SAME quarter of the prior year (Q4'25 vs Q4'24, not Q4'25 vs Q3'24) — corrects the earlier mismatched-period bug.
A22: Manufacturing Q1-Q3 Non-GAAP and Total Company Q1-Q2 Non-GAAP are marked 'n/a' as they were not disclosed at that granularity in the sourced releases.

Sheet 4. Product-Service Mix
A1: PRODUCT vs SERVICE REVENUE MIX - TOTAL COMPANY
A2: Green = formula link to '1. Raw Data' Table 5. Black = calculated on this tab. Scope note: CRL discloses Product/Service split at TOTAL COMPANY level only, not by segment -- this tab analyzes company-wide mix, not segment-level product/service detail.
A4: TABLE 1 - REVENUE MIX %, FY2024 vs FY2025 and Q4 2024 vs Q4 2025
A5: Revenue Type | B5: FY2024 $000s | C5: FY2024 Mix % | D5: FY2025 $000s | E5: FY2025 Mix % | F5: Mix Δ (pts) | G5: Q4'24 $000s | H5: Q4'24 Mix % | I5: Q4'25 $000s | J5: Q4'25 Mix % | K5: Q4 Mix Δ (pts)
A6: Service Revenue | B6: ='1. Raw Data'!D35 -> 3304138 | C6: =B6/'1. Raw Data'!D37 -> 0.81583876 | D6: ='1. Raw Data'!E35 -> 3250099 | E6: =D6/'1. Raw Data'!E37 -> 0.80941216 | F6: =(E6-C6)*100 -> -0.64266035 | G6: ='1. Raw Data'!B35 -> 811913 | H6: =G6/'1. Raw Data'!B37 -> 0.8098487 | I6: ='1. Raw Data'!C35 -> 803298 | J6: =I6/'1. Raw Data'!C37 -> 0.80796237 | K6: =(J6-H6)*100 -> -0.18863289
A7: Product Revenue | B7: ='1. Raw Data'!D36 -> 745851 | C7: =B7/'1. Raw Data'!D37 -> 0.18416124 | D7: ='1. Raw Data'!E36 -> 765283 | E7: =D7/'1. Raw Data'!E37 -> 0.19058784 | F7: =(E7-C7)*100 -> 0.64266035 | G7: ='1. Raw Data'!B36 -> 190636 | H7: =G7/'1. Raw Data'!B37 -> 0.1901513 | I7: ='1. Raw Data'!C36 -> 190929 | J7: =I7/'1. Raw Data'!C37 -> 0.19203763 | K7: =(J7-H7)*100 -> 0.18863289
A8: Total | B8: ='1. Raw Data'!D37 -> 4049989 | C8: 1 | D8: ='1. Raw Data'!E37 -> 4015382 | E8: 1 | F8: 0 | G8: ='1. Raw Data'!B37 -> 1002549 | H8: 1 | I8: ='1. Raw Data'!C37 -> 994227 | J8: 1 | K8: 0
A10: DRIVER COMMENTARY
A11: Service revenue share held broadly stable across FY2024->FY2025 (~81.6% of total both years), with a marginal decline as Product revenue grew slightly faster.
A13: Product revenue grew from $745.9M to $765.3M FY24->FY25 (+2.6%) even as Total Company organic revenue declined -1.6%, a mix-shift signal worth flagging to stakeholders.
A15: In Q4, the mix moved further toward Product (19.2% of Q4'25 revenue vs 19.0% in Q4'24), consistent with Manufacturing's Non-GAAP margin improvement seen in Tab 3 (27.4% -> 28.8% FY), since Manufacturing skews more product-heavy than DSA.
A17: This is a company-wide, not segment-level, view -- a genuine limitation of CRL's public disclosure, flagged rather than filled with an estimate.
A20: CHART DATA - Revenue Mix % (FY2024 vs FY2025)
A21: Revenue Type | B21: FY2024 Mix % | C21: FY2025 Mix %
A22: Service Revenue | B22: =C6 -> 0.81583876 | C22: =E6 -> 0.80941216
A23: Product Revenue | B23: =C7 -> 0.18416124 | C23: =E7 -> 0.19058784

Sheet Sources
A1: SOURCES - ALL FIGURES TRACE TO THESE PRIMARY DOCUMENTS
A2: No modelled, estimated, or assumed figures anywhere in this workbook. Every hardcoded (blue) cell traces to one of the sources below.
A4: # | B4: Document | C4: Publisher / Filing Type | D4: Date | E4: URL | F4: Used For
A5: 1 | B5: Q1 2025 Earnings Release | C5: Form 8-K, SEC EDGAR | D5: May 2025 | E5: https://www.sec.gov/Archives/edgar/data/0001100682/000110068225000019/crl1q25earningsrelease.htm | F5: Q1'25 vs Q1'24 segment revenue, GAAP/Non-GAAP margins (Tab 1 Table 7)
A6: 2 | B6: Q2 2025 Earnings Release | C6: Form 8-K, SEC EDGAR | D6: Aug 2025 | E6: https://www.sec.gov/Archives/edgar/data/0001100682/000110068225000032/crl2q25earningsrelease.htm | F6: Q2'25 vs Q2'24 segment revenue, GAAP/Non-GAAP margins (Tab 1 Table 7)
A7: 3 | B7: Q3 2025 Earnings Release | C7: Form 8-K, SEC EDGAR / businesswire.com | D7: Nov 5, 2025 | E7: https://www.sec.gov/Archives/edgar/data/0001100682/000110068225000041/crl3q25earningsrelease.htm | F7: Q3'25 quarter & 9-month YTD detail, organic growth bridge (Tab 1 Tables 2 & 4)
A8: 4 | B8: Q4 2024 / FY2024 Earnings Release | C8: Form 8-K, SEC EDGAR / ir.criver.com | D8: Feb 19, 2025 | E8: https://ir.criver.com/news-releases/news-release-details/charles-river-laboratories-announces-fourth-quarter-and-full-13 | F8: FY2024 segment margins, Q4 2024 quarterly detail (Tab 1 Tables 1 & 3, Tab 1 Table 7)
A9: 5 | B9: Q4 2025 / FY2025 Earnings Release & FY2026 Guidance | C9: Form 8-K, SEC EDGAR / businesswire.com / ir.criver.com | D9: Feb 18, 2026 | E9: https://www.businesswire.com/news/home/20260218016453/en/Charles-River-Laboratories-Announces-Fourth-Quarter-and-Full-Year-2025-Results-and-Provides-2026-Guidance | F9: FY2024/FY2025 segment revenue & margins, Q4'25 detail, Product/Service split, 2026 guidance (Tab 1 Tables 1, 3, 5, 6, 7)
A10: 6 | B10: FY2025 Form 10-K | C10: SEC EDGAR, CIK 0001100682 | D10: Filed Feb 18, 2026 | E10: https://www.sec.gov/cgi-bin/browse-edgar?action=getcompany&CIK=0001100682 | F10: Corroborates full-year segment figures and revenue disaggregation basis
A12: Verification method:
A13: - Every segment/total figure was cross-checked: segments sum to disclosed totals (Table 1, 2, 3, 5 in Raw Data).
A14: - Organic growth bridge (Reported - FX - Divestiture = Organic) independently recalculated and matched to CRL's own disclosed organic growth % for all four segments.
A15: - FY2025 GAAP margins recalculated from Op Income / Revenue and matched to disclosed rounded figures (RMS 5.3%, DSA 17.7%, Manufacturing -24.0%).
A16: - Where a figure was not disclosed at the required granularity (e.g. Manufacturing quarterly Non-GAAP margin, Q1-Q2 Total Company quarterly margin), it is marked 'n/a' rather than estimated.
